Workbook

Sheet PROJECT OVERVIEW
A1: SYNTHETIC CLAIMS OPPORTUNITY PORTFOLIO PROJECT
A4: Project objective | B4: Consolidated 560 synthetic claims across five source-report categories and 12 analyst views. Developed formula-driven classifications, three dashboard visualizations, linked record-level views, and independent audit controls that verified unique claim IDs, source-report totals, indicator distributions, and complete analyst-level coverage with zero unexplained differences.
A7: Scope | B7: 560 fully synthetic claims across 12 fictional claims analysts and five opportunity indicators.
A9: Tools demonstrated | B9: Formula-driven classifications, text-search logic, conditional formatting, dashboard KPIs and charts, linked analyst views, and independent reconciliation controls.
A11: Fictional reporting date | B11: December 31, 2031. All time-dependent statuses and classifications are interpreted relative to this fictional reporting date.
A13: Data statement | B13: All names, organizations, identifiers, dates, amounts, evaluator names, statuses, and alert text are synthetic and fictional.
A15: Methodology | B15: For each claim, an indicator is set to ‘Y’ when the claim appears on the corresponding synthetic source report: settlement authorization, open stipulation without C&R, pending QME, automated claim alert, or inactive customer. ”
A17: Important limitation | B17: Opportunity Signal Level is determined solely by active-indicator count: one indicator is classified as Single-Signal, two as Multi-Signal, three as Elevated Multi-Signal, four as High Multi-Signal, and five as Maximum Multi-Signal.
A19: Privacy statement | B19: This workbook was independently recreated for public portfolio use and contains no internal paths, personal contact details, employer-specific system names, or original claim-level values.
A21: Glossary | B21: C&R = Compromise and Release; MMI = Maximum Medical Improvement; MSA = Medicare Set-Aside; QME = Qualified Medical Evaluator.
A23: Blank-cell handling | B23: Optional fields remain blank when no value applies. Linked analyst views use blank-safe formulas so missing dates and amounts do not display as 1900 dates or zero values.

Sheet MASTER DATA
A1: Synthetic Claim ID | B1: Synthetic Claimant | C1: Claims Analyst | D1: Synthetic Policyholder | E1: Date of Injury | F1: Settlement Authorization (Y/N) | G1: Authorized Amount | H1: Authorized By | I1: Authorization Date | J1: Open Stipulation Without C&R (Y/N) | K1: First Stipulation Date | L1: Litigated (Y/N) | M1: Pending QME (Y/N) | N1: QME Date | O1: QME Evaluator | P1: Automated Claim Alert (Y/N) | Q1: Current Automated Alert(s) | R1: Previous Automated Alert(s) | S1: Inactive Customer (Y/N) | T1: Policy Expiration Date | U1: Alert Contains Surgery Request (Y/N) | V1: Alert Contains MMI (Y/N) | W1: Alert Contains Denied Treatment (Y/N) | X1: Alert Contains Specialist Consultation (Y/N) | Y1: Alert Contains Non-Renewed Account (Y/N) | Z1: Alert Contains MSA Eligibility (Y/N) | AA1: Active Opportunity Indicators | AB1: Opportunity Signal Level | AC1: Reports Appearing On
A2: SYN-CLM-0001 | B2: Synthetic Claimant 0001 | C2: Claims Analyst A | D2: Synthetic Policyholder 034, LLC | E2: 44113 | F2: Y | G2: 156750 | H2: Synthetic Approver 07 | I2: 44650 | J2: N | L2: N | M2: N | P2: Y | Q2: MMI Date Reported; Non-Renewed Account; MSA Eligible in Next 3 Years | S2: N | U2: =IF(ISNUMBER(SEARCH("SURGERY",Q2&" "&R2)),"Y","N") -> N | V2: =IF(ISNUMBER(SEARCH("MMI",Q2&" "&R2)),"Y","N") -> Y | W2: =IF(ISNUMBER(SEARCH("DENIED TREATMENT",Q2&" "&R2)),"Y","N") -> N | X2: =IF(ISNUMBER(SEARCH("SPECIALIST CONSULTATION",Q2&" "&R2)),"Y","N") -> N | Y2: =IF(ISNUMBER(SEARCH("NON-RENEWED ACCOUNT",Q2&" "&R2)),"Y","N") -> Y | Z2: =IF(ISNUMBER(SEARCH("MSA ELIGIBLE",Q2&" "&R2)),"Y","N") -> Y | AA2: =COUNTIF(F2,"Y")+COUNTIF(J2,"Y")+COUNTIF(M2,"Y")+COUNTIF(P2,"Y")+COUNTIF(S2,"Y") -> 2 | AB2: =IF(AA2=5,"MAXIMUM MULTI-SIGNAL",IF(AA2=4,"HIGH MULTI-SIGNAL",IF(AA2=3,"ELEVATED MULTI-SIGNAL",IF(AA2=2,"MULTI-SIGNAL","SINGLE-SIGNAL")))) -> MULTI-SIGNAL | AC2: =IF(F2="Y","Settlement Authorization","")&IF(J2="Y",IF(F2="Y"," | ","")&"Open Stipulation","")&IF(M2="Y",IF(OR(F2="Y",J2="Y")," | ","")&"Pending QME","")&IF(P2="Y",IF(OR(F2="Y",J2="Y",M2="Y")," | ","")&"Automated Claim Alert","")&IF(S2="Y",IF(OR(F2="Y",J2="Y",M2="Y",P2="Y")," | ","")&"Inactive Customer","") -> Settlement Authorization | Automated Claim Alert
A3: SYN-CLM-0002 | B3: Synthetic Claimant 0002 | C3: Claims Analyst F | D3: Synthetic Policyholder 170, LLC | E3: 43714 | F3: Y | G3: 21750 | H3: Synthetic Approver 04 | I3: 44940 | J3: N | L3: N | M3: N | P3: Y | Q3: Non-Renewed Account; Denied Treatment Requests; Surgery Requested | R3: MSA Eligible in Next 3 Years; Specialist Consultation Requested | S3: Y | T3: 44492 | U3: =IF(ISNUMBER(SEARCH("SURGERY",Q3&" "&R3)),"Y","N") -> Y | V3: =IF(ISNUMBER(SEARCH("MMI",Q3&" "&R3)),"Y","N") -> N | W3: =IF(ISNUMBER(SEARCH("DENIED TREATMENT",Q3&" "&R3)),"Y","N") -> Y | X3: =IF(ISNUMBER(SEARCH("SPECIALIST CONSULTATION",Q3&" "&R3)),"Y","N") -> Y | Y3: =IF(ISNUMBER(SEARCH("NON-RENEWED ACCOUNT",Q3&" "&R3)),"Y","N") -> Y | Z3: =IF(ISNUMBER(SEARCH("MSA ELIGIBLE",Q3&" "&R3)),"Y","N") -> Y | AA3: =COUNTIF(F3,"Y")+COUNTIF(J3,"Y")+COUNTIF(M3,"Y")+COUNTIF(P3,"Y")+COUNTIF(S3,"Y") -> 3 | AB3: =IF(AA3=5,"MAXIMUM MULTI-SIGNAL",IF(AA3=4,"HIGH MULTI-SIGNAL",IF(AA3=3,"ELEVATED MULTI-SIGNAL",IF(AA3=2,"MULTI-SIGNAL","SINGLE-SIGNAL")))) -> ELEVATED MULTI-SIGNAL | AC3: =IF(F3="Y","Settlement Authorization","")&IF(J3="Y",IF(F3="Y"," | ","")&"Open Stipulation","")&IF(M3="Y",IF(OR(F3="Y",J3="Y")," | ","")&"Pending QME","")&IF(P3="Y",IF(OR(F3="Y",J3="Y",M3="Y")," | ","")&"Automated Claim Alert","")&IF(S3="Y",IF(OR(F3="Y",J3="Y",M3="Y",P3="Y")," | ","")&"Inactive Customer","") -> Settlement Authorization | Automated Claim Alert | Inactive Customer
A4: SYN-CLM-0003 | B4: Synthetic Claimant 0003 | C4: Claims Analyst G | D4: Synthetic Policyholder 147, LLC | E4: 45745 | F4: Y | G4: 138750 | H4: Synthetic Approver 11 | I4: 46948 | J4: N | L4: N | M4: N | P4: N | S4: N | U4: =IF(ISNUMBER(SEARCH("SURGERY",Q4&" "&R4)),"Y","N") -> N | V4: =IF(ISNUMBER(SEARCH("MMI",Q4&" "&R4)),"Y","N") -> N | W4: =IF(ISNUMBER(SEARCH("DENIED TREATMENT",Q4&" "&R4)),"Y","N") -> N | X4: =IF(ISNUMBER(SEARCH("SPECIALIST CONSULTATION",Q4&" "&R4)),"Y","N") -> N | Y4: =IF(ISNUMBER(SEARCH("NON-RENEWED ACCOUNT",Q4&" "&R4)),"Y","N") -> N | Z4: =IF(ISNUMBER(SEARCH("MSA ELIGIBLE",Q4&" "&R4)),"Y","N") -> N | AA4: =COUNTIF(F4,"Y")+COUNTIF(J4,"Y")+COUNTIF(M4,"Y")+COUNTIF(P4,"Y")+COUNTIF(S4,"Y") -> 1 | AB4: =IF(AA4=5,"MAXIMUM MULTI-SIGNAL",IF(AA4=4,"HIGH MULTI-SIGNAL",IF(AA4=3,"ELEVATED MULTI-SIGNAL",IF(AA4=2,"MULTI-SIGNAL","SINGLE-SIGNAL")))) -> SINGLE-SIGNAL | AC4: =IF(F4="Y","Settlement Authorization","")&IF(J4="Y",IF(F4="Y"," | ","")&"Open Stipulation","")&IF(M4="Y",IF(OR(F4="Y",J4="Y")," | ","")&"Pending QME","")&IF(P4="Y",IF(OR(F4="Y",J4="Y",M4="Y")," | ","")&"Automated Claim Alert","")&IF(S4="Y",IF(OR(F4="Y",J4="Y",M4="Y",P4="Y")," | ","")&"Inactive Customer","") -> Settlement Authorization
A5: SYN-CLM-0004 | B5: Synthetic Claimant 0004 | C5: Claims Analyst J | D5: Synthetic Policyholder 118, LLC | E5: 45285 | F5: Y | G5: 109000 | H5: Synthetic Approver 01 | I5: 45783 | J5: N | L5: Y | M5: N | P5: N | S5: N | U5: =IF(ISNUMBER(SEARCH("SURGERY",Q5&" "&R5)),"Y","N") -> N | V5: =IF(ISNUMBER(SEARCH("MMI",Q5&" "&R5)),"Y","N") -> N | W5: =IF(ISNUMBER(SEARCH("DENIED TREATMENT",Q5&" "&R5)),"Y","N") -> N | X5: =IF(ISNUMBER(SEARCH("SPECIALIST CONSULTATION",Q5&" "&R5)),"Y","N") -> N | Y5: =IF(ISNUMBER(SEARCH("NON-RENEWED ACCOUNT",Q5&" "&R5)),"Y","N") -> N | Z5: =IF(ISNUMBER(SEARCH("MSA ELIGIBLE",Q5&" "&R5)),"Y","N") -> N | AA5: =COUNTIF(F5,"Y")+COUNTIF(J5,"Y")+COUNTIF(M5,"Y")+COUNTIF(P5,"Y")+COUNTIF(S5,"Y") -> 1 | AB5: =IF(AA5=5,"MAXIMUM MULTI-SIGNAL",IF(AA5=4,"HIGH MULTI-SIGNAL",IF(AA5=3,"ELEVATED MULTI-SIGNAL",IF(AA5=2,"MULTI-SIGNAL","SINGLE-SIGNAL")))) -> SINGLE-SIGNAL | AC5: =IF(F5="Y","Settlement Authorization","")&IF(J5="Y",IF(F5="Y"," | ","")&"Open Stipulation","")&IF(M5="Y",IF(OR(F5="Y",J5="Y")," | ","")&"Pending QME","")&IF(P5="Y",IF(OR(F5="Y",J5="Y",M5="Y")," | ","")&"Automated Claim Alert","")&IF(S5="Y",IF(OR(F5="Y",J5="Y",M5="Y",P5="Y")," | ","")&"Inactive Customer","") -> Settlement Authorization
A6: SYN-CLM-0005 | B6: Synthetic Claimant 0005 | C6: Claims Analyst A | D6: Synthetic Policyholder 129, LLC | E6: 45421 | F6: Y | G6: 108000 | H6: Synthetic Approver 01 | I6: 47152 | J6: N | L6: Y | M6: N | P6: N | S6: N | U6: =IF(ISNUMBER(SEARCH("SURGERY",Q6&" "&R6)),"Y","N") -> N | V6: =IF(ISNUMBER(SEARCH("MMI",Q6&" "&R6)),"Y","N") -> N | W6: =IF(ISNUMBER(SEARCH("DENIED TREATMENT",Q6&" "&R6)),"Y","N") -> N | X6: =IF(ISNUMBER(SEARCH("SPECIALIST CONSULTATION",Q6&" "&R6)),"Y","N") -> N | Y6: =IF(ISNUMBER(SEARCH("NON-RENEWED ACCOUNT",Q6&" "&R6)),"Y","N") -> N | Z6: =IF(ISNUMBER(SEARCH("MSA ELIGIBLE",Q6&" "&R6)),"Y","N") -> N | AA6: =COUNTIF(F6,"Y")+COUNTIF(J6,"Y")+COUNTIF(M6,"Y")+COUNTIF(P6,"Y")+COUNTIF(S6,"Y") -> 1 | AB6: =IF(AA6=5,"MAXIMUM MULTI-SIGNAL",IF(AA6=4,"HIGH MULTI-SIGNAL",IF(AA6=3,"ELEVATED MULTI-SIGNAL",IF(AA6=2,"MULTI-SIGNAL","SINGLE-SIGNAL")))) -> SINGLE-SIGNAL | AC6: =IF(F6="Y","Settlement Authorization","")&IF(J6="Y",IF(F6="Y"," | ","")&"Open Stipulation","")&IF(M6="Y",IF(OR(F6="Y",J6="Y")," | ","")&"Pending QME","")&IF(P6="Y",IF(OR(F6="Y",J6="Y",M6="Y")," | ","")&"Automated Claim Alert","")&IF(S6="Y",IF(OR(F6="Y",J6="Y",M6="Y",P6="Y")," | ","")&"Inactive Customer","") -> Settlement Authorization
A7: SYN-CLM-0006 | B7: Synthetic Claimant 0006 | C7: Claims Analyst A | D7: Synthetic Policyholder 167, LLC | E7: 44212 | F7: Y | G7: 25250 | H7: Synthetic Approver 09 | I7: 45671 | J7: N | L7: N | M7: N | P7: N | S7: N | U7: =IF(ISNUMBER(SEARCH("SURGERY",Q7&" "&R7)),"Y","N") -> N | V7: =IF(ISNUMBER(SEARCH("MMI",Q7&" "&R7)),"Y","N") -> N | W7: =IF(ISNUMBER(SEARCH("DENIED TREATMENT",Q7&" "&R7)),"Y","N") -> N | X7: =IF(ISNUMBER(SEARCH("SPECIALIST CONSULTATION",Q7&" "&R7)),"Y","N") -> N | Y7: =IF(ISNUMBER(SEARCH("NON-RENEWED ACCOUNT",Q7&" "&R7)),"Y","N") -> N | Z7: =IF(ISNUMBER(SEARCH("MSA ELIGIBLE",Q7&" "&R7)),"Y","N") -> N | AA7: =COUNTIF(F7,"Y")+COUNTIF(J7,"Y")+COUNTIF(M7,"Y")+COUNTIF(P7,"Y")+COUNTIF(S7,"Y") -> 1 | AB7: =IF(AA7=5,"MAXIMUM MULTI-SIGNAL",IF(AA7=4,"HIGH MULTI-SIGNAL",IF(AA7=3,"ELEVATED MULTI-SIGNAL",IF(AA7=2,"MULTI-SIGNAL","SINGLE-SIGNAL")))) -> SINGLE-SIGNAL | AC7: =IF(F7="Y","Settlement Authorization","")&IF(J7="Y",IF(F7="Y"," | ","")&"Open Stipulation","")&IF(M7="Y",IF(OR(F7="Y",J7="Y")," | ","")&"Pending QME","")&IF(P7="Y",IF(OR(F7="Y",J7="Y",M7="Y")," | ","")&"Automated Claim Alert","")&IF(S7="Y",IF(OR(F7="Y",J7="Y",M7="Y",P7="Y")," | ","")&"Inactive Customer","") -> Settlement Authorization
A8: SYN-CLM-0007 | B8: Synthetic Claimant 0007 | C8: Claims Analyst A | D8: Synthetic Policyholder 080, LLC | E8: 44367 | F8: Y | G8: 55500 | H8: Synthetic Approver 01 | I8: 45792 | J8: N | L8: N | M8: N | P8: N | S8: N | U8: =IF(ISNUMBER(SEARCH("SURGERY",Q8&" "&R8)),"Y","N") -> N | V8: =IF(ISNUMBER(SEARCH("MMI",Q8&" "&R8)),"Y","N") -> N | W8: =IF(ISNUMBER(SEARCH("DENIED TREATMENT",Q8&" "&R8)),"Y","N") -> N | X8: =IF(ISNUMBER(SEARCH("SPECIALIST CONSULTATION",Q8&" "&R8)),"Y","N") -> N | Y8: =IF(ISNUMBER(SEARCH("NON-RENEWED ACCOUNT",Q8&" "&R8)),"Y","N") -> N | Z8: =IF(ISNUMBER(SEARCH("MSA ELIGIBLE",Q8&" "&R8)),"Y","N") -> N | AA8: =COUNTIF(F8,"Y")+COUNTIF(J8,"Y")+COUNTIF(M8,"Y")+COUNTIF(P8,"Y")+COUNTIF(S8,"Y") -> 1 | AB8: =IF(AA8=5,"MAXIMUM MULTI-SIGNAL",IF(AA8=4,"HIGH MULTI-SIGNAL",IF(AA8=3,"ELEVATED MULTI-SIGNAL",IF(AA8=2,"MULTI-SIGNAL","SINGLE-SIGNAL")))) -> SINGLE-SIGNAL | AC8: =IF(F8="Y","Settlement Authorization","")&IF(J8="Y",IF(F8="Y"," | ","")&"Open Stipulation","")&IF(M8="Y",IF(OR(F8="Y",J8="Y")," | ","")&"Pending QME","")&IF(P8="Y",IF(OR(F8="Y",J8="Y",M8="Y")," | ","")&"Automated Claim Alert","")&IF(S8="Y",IF(OR(F8="Y",J8="Y",M8="Y",P8="Y")," | ","")&"Inactive Customer","") -> Settlement Authorization
A9: SYN-CLM-0008 | B9: Synthetic Claimant 0008 | C9: Claims Analyst A | D9: Synthetic Policyholder 153, LLC | E9: 45296 | F9: Y | G9: 99250 | H9: Synthetic Approver 06 | I9: 47034 | J9: N | L9: Y | M9: N | P9: N | S9: N | U9: =IF(ISNUMBER(SEARCH("SURGERY",Q9&" "&R9)),"Y","N") -> N | V9: =IF(ISNUMBER(SEARCH("MMI",Q9&" "&R9)),"Y","N") -> N | W9: =IF(ISNUMBER(SEARCH("DENIED TREATMENT",Q9&" "&R9)),"Y","N") -> N | X9: =IF(ISNUMBER(SEARCH("SPECIALIST CONSULTATION",Q9&" "&R9)),"Y","N") -> N | Y9: =IF(ISNUMBER(SEARCH("NON-RENEWED ACCOUNT",Q9&" "&R9)),"Y","N") -> N | Z9: =IF(ISNUMBER(SEARCH("MSA ELIGIBLE",Q9&" "&R9)),"Y","N") -> N | AA9: =COUNTIF(F9,"Y")+COUNTIF(J9,"Y")+COUNTIF(M9,"Y")+COUNTIF(P9,"Y")+COUNTIF(S9,"Y") -> 1 | AB9: =IF(AA9=5,"MAXIMUM MULTI-SIGNAL",IF(AA9=4,"HIGH MULTI-SIGNAL",IF(AA9=3,"ELEVATED MULTI-SIGNAL",IF(AA9=2,"MULTI-SIGNAL","SINGLE-SIGNAL")))) -> SINGLE-SIGNAL | AC9: =IF(F9="Y","Settlement Authorization","")&IF(J9="Y",IF(F9="Y"," | ","")&"Open Stipulation","")&IF(M9="Y",IF(OR(F9="Y",J9="Y")," | ","")&"Pending QME","")&IF(P9="Y",IF(OR(F9="Y",J9="Y",M9="Y")," | ","")&"Automated Claim Alert","")&IF(S9="Y",IF(OR(F9="Y",J9="Y",M9="Y",P9="Y")," | ","")&"Inactive Customer","") -> Settlement Authorization
A10: SYN-CLM-0009 | B10: Synthetic Claimant 0009 | C10: Claims Analyst A | D10: Synthetic Policyholder 143, LLC | E10: 45045 | F10: Y | G10: 36250 | H10: Synthetic Approver 02 | I10: 46628 | J10: Y | K10: 45616 | L10: Y | M10: N | P10: N | S10: N | U10: =IF(ISNUMBER(SEARCH("SURGERY",Q10&" "&R10)),"Y","N") -> N | V10: =IF(ISNUMBER(SEARCH("MMI",Q10&" "&R10)),"Y","N") -> N | W10: =IF(ISNUMBER(SEARCH("DENIED TREATMENT",Q10&" "&R10)),"Y","N") -> N | X10: =IF(ISNUMBER(SEARCH("SPECIALIST CONSULTATION",Q10&" "&R10)),"Y","N") -> N | Y10: =IF(ISNUMBER(SEARCH("NON-RENEWED ACCOUNT",Q10&" "&R10)),"Y","N") -> N | Z10: =IF(ISNUMBER(SEARCH("MSA ELIGIBLE",Q10&" "&R10)),"Y","N") -> N | AA10: =COUNTIF(F10,"Y")+COUNTIF(J10,"Y")+COUNTIF(M10,"Y")+COUNTIF(P10,"Y")+COUNTIF(S10,"Y") -> 2 | AB10: =IF(AA10=5,"MAXIMUM MULTI-SIGNAL",IF(AA10=4,"HIGH MULTI-SIGNAL",IF(AA10=3,"ELEVATED MULTI-SIGNAL",IF(AA10=2,"MULTI-SIGNAL","SINGLE-SIGNAL")))) -> MULTI-SIGNAL | AC10: =IF(F10="Y","Settlement Authorization","")&IF(J10="Y",IF(F10="Y"," | ","")&"Open Stipulation","")&IF(M10="Y",IF(OR(F10="Y",J10="Y")," | ","")&"Pending QME","")&IF(P10="Y",IF(OR(F10="Y",J10="Y",M10="Y")," | ","")&"Automated Claim Alert","")&IF(S10="Y",IF(OR(F10="Y",J10="Y",M10="Y",P10="Y")," | ","")&"Inactive Customer","") -> Settlement Authorization | Open Stipulation
A11: SYN-CLM-0010 | B11: Synthetic Claimant 0010 | C11: Claims Analyst A | D11: Synthetic Policyholder 172, LLC | E11: 45075 | F11: Y | G11: 99500 | H11: Synthetic Approver 08 | I11: 45452 | J11: N | L11: N | M11: N | P11: N | S11: N | U11: =IF(ISNUMBER(SEARCH("SURGERY",Q11&" "&R11)),"Y","N") -> N | V11: =IF(ISNUMBER(SEARCH("MMI",Q11&" "&R11)),"Y","N") -> N | W11: =IF(ISNUMBER(SEARCH("DENIED TREATMENT",Q11&" "&R11)),"Y","N") -> N | X11: =IF(ISNUMBER(SEARCH("SPECIALIST CONSULTATION",Q11&" "&R11)),"Y","N") -> N | Y11: =IF(ISNUMBER(SEARCH("NON-RENEWED ACCOUNT",Q11&" "&R11)),"Y","N") -> N | Z11: =IF(ISNUMBER(SEARCH("MSA ELIGIBLE",Q11&" "&R11)),"Y","N") -> N | AA11: =COUNTIF(F11,"Y")+COUNTIF(J11,"Y")+COUNTIF(M11,"Y")+COUNTIF(P11,"Y")+COUNTIF(S11,"Y") -> 1 | AB11: =IF(AA11=5,"MAXIMUM MULTI-SIGNAL",IF(AA11=4,"HIGH MULTI-SIGNAL",IF(AA11=3,"ELEVATED MULTI-SIGNAL",IF(AA11=2,"MULTI-SIGNAL","SINGLE-SIGNAL")))) -> SINGLE-SIGNAL | AC11: =IF(F11="Y","Settlement Authorization","")&IF(J11="Y",IF(F11="Y"," | ","")&"Open Stipulation","")&IF(M11="Y",IF(OR(F11="Y",J11="Y")," | ","")&"Pending QME","")&IF(P11="Y",IF(OR(F11="Y",J11="Y",M11="Y")," | ","")&"Automated Claim Alert","")&IF(S11="Y",IF(OR(F11="Y",J11="Y",M11="Y",P11="Y")," | ","")&"Inactive Customer","") -> Settlement Authorization
A12: SYN-CLM-0011 | B12: Synthetic Claimant 0011 | C12: Claims Analyst A | D12: Synthetic Policyholder 103, LLC | E12: 46061 | F12: Y | G12: 151750 | H12: Synthetic Approver 07 | I12: 47491 | J12: N | L12: Y | M12: N | P12: N | S12: N | U12: =IF(ISNUMBER(SEARCH("SURGERY",Q12&" "&R12)),"Y","N") -> N | V12: =IF(ISNUMBER(SEARCH("MMI",Q12&" "&R12)),"Y","N") -> N | W12: =IF(ISNUMBER(SEARCH("DENIED TREATMENT",Q12&" "&R12)),"Y","N") -> N | X12: =IF(ISNUMBER(SEARCH("SPECIALIST CONSULTATION",Q12&" "&R12)),"Y","N") -> N | Y12: =IF(ISNUMBER(SEARCH("NON-RENEWED ACCOUNT",Q12&" "&R12)),"Y","N") -> N | Z12: =IF(ISNUMBER(SEARCH("MSA ELIGIBLE",Q12&" "&R12)),"Y","N") -> N | AA12: =COUNTIF(F12,"Y")+COUNTIF(J12,"Y")+COUNTIF(M12,"Y")+COUNTIF(P12,"Y")+COUNTIF(S12,"Y") -> 1 | AB12: =IF(AA12=5,"MAXIMUM MULTI-SIGNAL",IF(AA12=4,"HIGH MULTI-SIGNAL",IF(AA12=3,"ELEVATED MULTI-SIGNAL",IF(AA12=2,"MULTI-SIGNAL","SINGLE-SIGNAL")))) -> SINGLE-SIGNAL | AC12: =IF(F12="Y","Settlement Authorization","")&IF(J12="Y",IF(F12="Y"," | ","")&"Open Stipulation","")&IF(M12="Y",IF(OR(F12="Y",J12="Y")," | ","")&"Pending QME","")&IF(P12="Y",IF(OR(F12="Y",J12="Y",M12="Y")," | ","")&"Automated Claim Alert","")&IF(S12="Y",IF(OR(F12="Y",J12="Y",M12="Y",P12="Y")," | ","")&"Inactive Customer","") -> Settlement Authorization
A13: SYN-CLM-0012 | B13: Synthetic Claimant 0012 | C13: Claims Analyst A | D13: Synthetic Policyholder 125, LLC | E13: 43150 | F13: N | J13: Y | K13: 44474 | L13: Y | M13: N | P13: N | S13: N | U13: =IF(ISNUMBER(SEARCH("SURGERY",Q13&" "&R13)),"Y","N") -> N | V13: =IF(ISNUMBER(SEARCH("MMI",Q13&" "&R13)),"Y","N") -> N | W13: =IF(ISNUMBER(SEARCH("DENIED TREATMENT",Q13&" "&R13)),"Y","N") -> N | X13: =IF(ISNUMBER(SEARCH("SPECIALIST CONSULTATION",Q13&" "&R13)),"Y","N") -> N | Y13: =IF(ISNUMBER(SEARCH("NON-RENEWED ACCOUNT",Q13&" "&R13)),"Y","N") -> N | Z13: =IF(ISNUMBER(SEARCH("MSA ELIGIBLE",Q13&" "&R13)),"Y","N") -> N | AA13: =COUNTIF(F13,"Y")+COUNTIF(J13,"Y")+COUNTIF(M13,"Y")+COUNTIF(P13,"Y")+COUNTIF(S13,"Y") -> 1 | AB13: =IF(AA13=5,"MAXIMUM MULTI-SIGNAL",IF(AA13=4,"HIGH MULTI-SIGNAL",IF(AA13=3,"ELEVATED MULTI-SIGNAL",IF(AA13=2,"MULTI-SIGNAL","SINGLE-SIGNAL")))) -> SINGLE-SIGNAL | AC13: =IF(F13="Y","Settlement Authorization","")&IF(J13="Y",IF(F13="Y"," | ","")&"Open Stipulation","")&IF(M13="Y",IF(OR(F13="Y",J13="Y")," | ","")&"Pending QME","")&IF(P13="Y",IF(OR(F13="Y",J13="Y",M13="Y")," | ","")&"Automated Claim Alert","")&IF(S13="Y",IF(OR(F13="Y",J13="Y",M13="Y",P13="Y")," | ","")&"Inactive Customer","") -> Open Stipulation
A14: SYN-CLM-0013 | B14: Synthetic Claimant 0013 | C14: Claims Analyst A | D14: Synthetic Policyholder 002, LLC | E14: 43189 | F14: N | J14: N | M14: N | P14: N | S14: Y | T14: 45140 | U14: =IF(ISNUMBER(SEARCH("SURGERY",Q14&" "&R14)),"Y","N") -> N | V14: =IF(ISNUMBER(SEARCH("MMI",Q14&" "&R14)),"Y","N") -> N | W14: =IF(ISNUMBER(SEARCH("DENIED TREATMENT",Q14&" "&R14)),"Y","N") -> N | X14: =IF(ISNUMBER(SEARCH("SPECIALIST CONSULTATION",Q14&" "&R14)),"Y","N") -> N | Y14: =IF(ISNUMBER(SEARCH("NON-RENEWED ACCOUNT",Q14&" "&R14)),"Y","N") -> N | Z14: =IF(ISNUMBER(SEARCH("MSA ELIGIBLE",Q14&" "&R14)),"Y","N") -> N | AA14: =COUNTIF(F14,"Y")+COUNTIF(J14,"Y")+COUNTIF(M14,"Y")+COUNTIF(P14,"Y")+COUNTIF(S14,"Y") -> 1 | AB14: =IF(AA14=5,"MAXIMUM MULTI-SIGNAL",IF(AA14=4,"HIGH MULTI-SIGNAL",IF(AA14=3,"ELEVATED MULTI-SIGNAL",IF(AA14=2,"MULTI-SIGNAL","SINGLE-SIGNAL")))) -> SINGLE-SIGNAL | AC14: =IF(F14="Y","Settlement Authorization","")&IF(J14="Y",IF(F14="Y"," | ","")&"Open Stipulation","")&IF(M14="Y",IF(OR(F14="Y",J14="Y")," | ","")&"Pending QME","")&IF(P14="Y",IF(OR(F14="Y",J14="Y",M14="Y")," | ","")&"Automated Claim Alert","")&IF(S14="Y",IF(OR(F14="Y",J14="Y",M14="Y",P14="Y")," | ","")&"Inactive Customer","") -> Inactive Customer
A15: SYN-CLM-0014 | B15: Synthetic Claimant 0014 | C15: Claims Analyst A | D15: Synthetic Policyholder 171, LLC | E15: 43724 | F15: N | J15: N | M15: N | P15: N | S15: Y | T15: 44294 | U15: =IF(ISNUMBER(SEARCH("SURGERY",Q15&" "&R15)),"Y","N") -> N | V15: =IF(ISNUMBER(SEARCH("MMI",Q15&" "&R15)),"Y","N") -> N | W15: =IF(ISNUMBER(SEARCH("DENIED TREATMENT",Q15&" "&R15)),"Y","N") -> N | X15: =IF(ISNUMBER(SEARCH("SPECIALIST CONSULTATION",Q15&" "&R15)),"Y","N") -> N | Y15: =IF(ISNUMBER(SEARCH("NON-RENEWED ACCOUNT",Q15&" "&R15)),"Y","N") -> N | Z15: =IF(ISNUMBER(SEARCH("MSA ELIGIBLE",Q15&" "&R15)),"Y","N") -> N | AA15: =COUNTIF(F15,"Y")+COUNTIF(J15,"Y")+COUNTIF(M15,"Y")+COUNTIF(P15,"Y")+COUNTIF(S15,"Y") -> 1 | AB15: =IF(AA15=5,"MAXIMUM MULTI-SIGNAL",IF(AA15=4,"HIGH MULTI-SIGNAL",IF(AA15=3,"ELEVATED MULTI-SIGNAL",IF(AA15=2,"MULTI-SIGNAL","SINGLE-SIGNAL")))) -> SINGLE-SIGNAL | AC15: =IF(F15="Y","Settlement Authorization","")&IF(J15="Y",IF(F15="Y"," | ","")&"Open Stipulation","")&IF(M15="Y",IF(OR(F15="Y",J15="Y")," | ","")&"Pending QME","")&IF(P15="Y",IF(OR(F15="Y",J15="Y",M15="Y")," | ","")&"Automated Claim Alert","")&IF(S15="Y",IF(OR(F15="Y",J15="Y",M15="Y",P15="Y")," | ","")&"Inactive Customer","") -> Inactive Customer
A16: SYN-CLM-0015 | B16: Synthetic Claimant 0015 | C16: Claims Analyst A | D16: Synthetic Policyholder 056, LLC | E16: 44130 | F16: Y | G16: 107500 | H16: Synthetic Approver 12 | I16: 45894 | J16: N | L16: N | M16: N | P16: N | S16: N | U16: =IF(ISNUMBER(SEARCH("SURGERY",Q16&" "&R16)),"Y","N") -> N | V16: =IF(ISNUMBER(SEARCH("MMI",Q16&" "&R16)),"Y","N") -> N | W16: =IF(ISNUMBER(SEARCH("DENIED TREATMENT",Q16&" "&R16)),"Y","N") -> N | X16: =IF(ISNUMBER(SEARCH("SPECIALIST CONSULTATION",Q16&" "&R16)),"Y","N") -> N | Y16: =IF(ISNUMBER(SEARCH("NON-RENEWED ACCOUNT",Q16&" "&R16)),"Y","N") -> N | Z16: =IF(ISNUMBER(SEARCH("MSA ELIGIBLE",Q16&" "&R16)),"Y","N") -> N | AA16: =COUNTIF(F16,"Y")+COUNTIF(J16,"Y")+COUNTIF(M16,"Y")+COUNTIF(P16,"Y")+COUNTIF(S16,"Y") -> 1 | AB16: =IF(AA16=5,"MAXIMUM MULTI-SIGNAL",IF(AA16=4,"HIGH MULTI-SIGNAL",IF(AA16=3,"ELEVATED MULTI-SIGNAL",IF(AA16=2,"MULTI-SIGNAL","SINGLE-SIGNAL")))) -> SINGLE-SIGNAL | AC16: =IF(F16="Y","Settlement Authorization","")&IF(J16="Y",IF(F16="Y"," | ","")&"Open Stipulation","")&IF(M16="Y",IF(OR(F16="Y",J16="Y")," | ","")&"Pending QME","")&IF(P16="Y",IF(OR(F16="Y",J16="Y",M16="Y")," | ","")&"Automated Claim Alert","")&IF(S16="Y",IF(OR(F16="Y",J16="Y",M16="Y",P16="Y")," | ","")&"Inactive Customer","") -> Settlement Authorization
A17: SYN-CLM-0016 | B17: Synthetic Claimant 0016 | C17: Claims Analyst A | D17: Synthetic Policyholder 018, LLC | E17: 44236 | F17: Y | G17: 108750 | H17: Synthetic Approver 04 | I17: 45432 | J17: N | L17: N | M17: N | P17: N | S17: Y | T17: 45642 | U17: =IF(ISNUMBER(SEARCH("SURGERY",Q17&" "&R17)),"Y","N") -> N | V17: =IF(ISNUMBER(SEARCH("MMI",Q17&" "&R17)),"Y","N") -> N | W17: =IF(ISNUMBER(SEARCH("DENIED TREATMENT",Q17&" "&R17)),"Y","N") -> N | X17: =IF(ISNUMBER(SEARCH("SPECIALIST CONSULTATION",Q17&" "&R17)),"Y","N") -> N | Y17: =IF(ISNUMBER(SEARCH("NON-RENEWED ACCOUNT",Q17&" "&R17)),"Y","N") -> N | Z17: =IF(ISNUMBER(SEARCH("MSA ELIGIBLE",Q17&" "&R17)),"Y","N") -> N | AA17: =COUNTIF(F17,"Y")+COUNTIF(J17,"Y")+COUNTIF(M17,"Y")+COUNTIF(P17,"Y")+COUNTIF(S17,"Y") -> 2 | AB17: =IF(AA17=5,"MAXIMUM MULTI-SIGNAL",IF(AA17=4,"HIGH MULTI-SIGNAL",IF(AA17=3,"ELEVATED MULTI-SIGNAL",IF(AA17=2,"MULTI-SIGNAL","SINGLE-SIGNAL")))) -> MULTI-SIGNAL | AC17: =IF(F17="Y","Settlement Authorization","")&IF(J17="Y",IF(F17="Y"," | ","")&"Open Stipulation","")&IF(M17="Y",IF(OR(F17="Y",J17="Y")," | ","")&"Pending QME","")&IF(P17="Y",IF(OR(F17="Y",J17="Y",M17="Y")," | ","")&"Automated Claim Alert","")&IF(S17="Y",IF(OR(F17="Y",J17="Y",M17="Y",P17="Y")," | ","")&"Inactive Customer","") -> Settlement Authorization | Inactive Customer
A18: SYN-CLM-0017 | B18: Synthetic Claimant 0017 | C18: Claims Analyst A | D18: Synthetic Policyholder 028, LLC | E18: 43129 | F18: Y | G18: 27250 | H18: Synthetic Approver 05 | I18: 43305 | J18: N | L18: N | M18: N | P18: N | S18: N | U18: =IF(ISNUMBER(SEARCH("SURGERY",Q18&" "&R18)),"Y","N") -> N | V18: =IF(ISNUMBER(SEARCH("MMI",Q18&" "&R18)),"Y","N") -> N | W18: =IF(ISNUMBER(SEARCH("DENIED TREATMENT",Q18&" "&R18)),"Y","N") -> N | X18: =IF(ISNUMBER(SEARCH("SPECIALIST CONSULTATION",Q18&" "&R18)),"Y","N") -> N | Y18: =IF(ISNUMBER(SEARCH("NON-RENEWED ACCOUNT",Q18&" "&R18)),"Y","N") -> N | Z18: =IF(ISNUMBER(SEARCH("MSA ELIGIBLE",Q18&" "&R18)),"Y","N") -> N | AA18: =COUNTIF(F18,"Y")+COUNTIF(J18,"Y")+COUNTIF(M18,"Y")+COUNTIF(P18,"Y")+COUNTIF(S18,"Y") -> 1 | AB18: =IF(AA18=5,"MAXIMUM MULTI-SIGNAL",IF(AA18=4,"HIGH MULTI-SIGNAL",IF(AA18=3,"ELEVATED MULTI-SIGNAL",IF(AA18=2,"MULTI-SIGNAL","SINGLE-SIGNAL")))) -> SINGLE-SIGNAL | AC18: =IF(F18="Y","Settlement Authorization","")&IF(J18="Y",IF(F18="Y"," | ","")&"Open Stipulation","")&IF(M18="Y",IF(OR(F18="Y",J18="Y")," | ","")&"Pending QME","")&IF(P18="Y",IF(OR(F18="Y",J18="Y",M18="Y")," | ","")&"Automated Claim Alert","")&IF(S18="Y",IF(OR(F18="Y",J18="Y",M18="Y",P18="Y")," | ","")&"Inactive Customer","") -> Settlement Authorization
A19: SYN-CLM-0018 | B19: Synthetic Claimant 0018 | C19: Claims Analyst C | D19: Synthetic Policyholder 157, LLC | E19: 45454 | F19: N | J19: Y | K19: 46206 | L19: Y | M19: N | P19: Y | Q19: Surgery Requested; MSA Eligible in Next 3 Years; MMI Date Reported | R19: Specialist Consultation Requested | S19: N | U19: =IF(ISNUMBER(SEARCH("SURGERY",Q19&" "&R19)),"Y","N") -> Y | V19: =IF(ISNUMBER(SEARCH("MMI",Q19&" "&R19)),"Y","N") -> Y | W19: =IF(ISNUMBER(SEARCH("DENIED TREATMENT",Q19&" "&R19)),"Y","N") -> N | X19: =IF(ISNUMBER(SEARCH("SPECIALIST CONSULTATION",Q19&" "&R19)),"Y","N") -> Y | Y19: =IF(ISNUMBER(SEARCH("NON-RENEWED ACCOUNT",Q19&" "&R19)),"Y","N") -> N | Z19: =IF(ISNUMBER(SEARCH("MSA ELIGIBLE",Q19&" "&R19)),"Y","N") -> Y | AA19: =COUNTIF(F19,"Y")+COUNTIF(J19,"Y")+COUNTIF(M19,"Y")+COUNTIF(P19,"Y")+COUNTIF(S19,"Y") -> 2 | AB19: =IF(AA19=5,"MAXIMUM MULTI-SIGNAL",IF(AA19=4,"HIGH MULTI-SIGNAL",IF(AA19=3,"ELEVATED MULTI-SIGNAL",IF(AA19=2,"MULTI-SIGNAL","SINGLE-SIGNAL")))) -> MULTI-SIGNAL | AC19: =IF(F19="Y","Settlement Authorization","")&IF(J19="Y",IF(F19="Y"," | ","")&"Open Stipulation","")&IF(M19="Y",IF(OR(F19="Y",J19="Y")," | ","")&"Pending QME","")&IF(P19="Y",IF(OR(F19="Y",J19="Y",M19="Y")," | ","")&"Automated Claim Alert","")&IF(S19="Y",IF(OR(F19="Y",J19="Y",M19="Y",P19="Y")," | ","")&"Inactive Customer","") -> Open Stipulation | Automated Claim Alert
A20: SYN-CLM-0019 | B20: Synthetic Claimant 0019 | C20: Claims Analyst C | D20: Synthetic Policyholder 004, LLC | E20: 44294 | F20: N | J20: Y | K20: 44425 | L20: N | M20: N | P20: N | S20: Y | T20: 44951 | U20: =IF(ISNUMBER(SEARCH("SURGERY",Q20&" "&R20)),"Y","N") -> N | V20: =IF(ISNUMBER(SEARCH("MMI",Q20&" "&R20)),"Y","N") -> N | W20: =IF(ISNUMBER(SEARCH("DENIED TREATMENT",Q20&" "&R20)),"Y","N") -> N | X20: =IF(ISNUMBER(SEARCH("SPECIALIST CONSULTATION",Q20&" "&R20)),"Y","N") -> N | Y20: =IF(ISNUMBER(SEARCH("NON-RENEWED ACCOUNT",Q20&" "&R20)),"Y","N") -> N | Z20: =IF(ISNUMBER(SEARCH("MSA ELIGIBLE",Q20&" "&R20)),"Y","N") -> N | AA20: =COUNTIF(F20,"Y")+COUNTIF(J20,"Y")+COUNTIF(M20,"Y")+COUNTIF(P20,"Y")+COUNTIF(S20,"Y") -> 2 | AB20: =IF(AA20=5,"MAXIMUM MULTI-SIGNAL",IF(AA20=4,"HIGH MULTI-SIGNAL",IF(AA20=3,"ELEVATED MULTI-SIGNAL",IF(AA20=2,"MULTI-SIGNAL","SINGLE-SIGNAL")))) -> MULTI-SIGNAL | AC20: =IF(F20="Y","Settlement Authorization","")&IF(J20="Y",IF(F20="Y"," | ","")&"Open Stipulation","")&IF(M20="Y",IF(OR(F20="Y",J20="Y")," | ","")&"Pending QME","")&IF(P20="Y",IF(OR(F20="Y",J20="Y",M20="Y")," | ","")&"Automated Claim Alert","")&IF(S20="Y",IF(OR(F20="Y",J20="Y",M20="Y",P20="Y")," | ","")&"Inactive Customer","") -> Open Stipulation | Inactive Customer
A21: SYN-CLM-0020 | B21: Synthetic Claimant 0020 | C21: Claims Analyst C | D21: Synthetic Policyholder 115, LLC | E21: 43797 | F21: N | J21: Y | K21: 44459 | L21: N | M21: Y | N21: 44906 | O21: Synthetic QME Evaluator 25 | P21: N | S21: Y | T21: 44464 | U21: =IF(ISNUMBER(SEARCH("SURGERY",Q21&" "&R21)),"Y","N") -> N | V21: =IF(ISNUMBER(SEARCH("MMI",Q21&" "&R21)),"Y","N") -> N | W21: =IF(ISNUMBER(SEARCH("DENIED TREATMENT",Q21&" "&R21)),"Y","N") -> N | X21: =IF(ISNUMBER(SEARCH("SPECIALIST CONSULTATION",Q21&" "&R21)),"Y","N") -> N | Y21: =IF(ISNUMBER(SEARCH("NON-RENEWED ACCOUNT",Q21&" "&R21)),"Y","N") -> N | Z21: =IF(ISNUMBER(SEARCH("MSA ELIGIBLE",Q21&" "&R21)),"Y","N") -> N | AA21: =COUNTIF(F21,"Y")+COUNTIF(J21,"Y")+COUNTIF(M21,"Y")+COUNTIF(P21,"Y")+COUNTIF(S21,"Y") -> 3 | AB21: =IF(AA21=5,"MAXIMUM MULTI-SIGNAL",IF(AA21=4,"HIGH MULTI-SIGNAL",IF(AA21=3,"ELEVATED MULTI-SIGNAL",IF(AA21=2,"MULTI-SIGNAL","SINGLE-SIGNAL")))) -> ELEVATED MULTI-SIGNAL | AC21: =IF(F21="Y","Settlement Authorization","")&IF(J21="Y",IF(F21="Y"," | ","")&"Open Stipulation","")&IF(M21="Y",IF(OR(F21="Y",J21="Y")," | ","")&"Pending QME","")&IF(P21="Y",IF(OR(F21="Y",J21="Y",M21="Y")," | ","")&"Automated Claim Alert","")&IF(S21="Y",IF(OR(F21="Y",J21="Y",M21="Y",P21="Y")," | ","")&"Inactive Customer","") -> Open Stipulation | Pending QME | Inactive Customer
A22: SYN-CLM-0021 | B22: Synthetic Claimant 0021 | C22: Claims Analyst C | D22: Synthetic Policyholder 090, LLC | E22: 43386 | F22: Y | G22: 133500 | H22: Synthetic Approver 12 | I22: 43683 | J22: N | L22: Y | M22: N | P22: N | S22: N | U22: =IF(ISNUMBER(SEARCH("SURGERY",Q22&" "&R22)),"Y","N") -> N | V22: =IF(ISNUMBER(SEARCH("MMI",Q22&" "&R22)),"Y","N") -> N | W22: =IF(ISNUMBER(SEARCH("DENIED TREATMENT",Q22&" "&R22)),"Y","N") -> N | X22: =IF(ISNUMBER(SEARCH("SPECIALIST CONSULTATION",Q22&" "&R22)),"Y","N") -> N | Y22: =IF(ISNUMBER(SEARCH("NON-RENEWED ACCOUNT",Q22&" "&R22)),"Y","N") -> N | Z22: =IF(ISNUMBER(SEARCH("MSA ELIGIBLE",Q22&" "&R22)),"Y","N") -> N | AA22: =COUNTIF(F22,"Y")+COUNTIF(J22,"Y")+COUNTIF(M22,"Y")+COUNTIF(P22,"Y")+COUNTIF(S22,"Y") -> 1 | AB22: =IF(AA22=5,"MAXIMUM MULTI-SIGNAL",IF(AA22=4,"HIGH MULTI-SIGNAL",IF(AA22=3,"ELEVATED MULTI-SIGNAL",IF(AA22=2,"MULTI-SIGNAL","SINGLE-SIGNAL")))) -> SINGLE-SIGNAL | AC22: =IF(F22="Y","Settlement Authorization","")&IF(J22="Y",IF(F22="Y"," | ","")&"Open Stipulation","")&IF(M22="Y",IF(OR(F22="Y",J22="Y")," | ","")&"Pending QME","")&IF(P22="Y",IF(OR(F22="Y",J22="Y",M22="Y")," | ","")&"Automated Claim Alert","")&IF(S22="Y",IF(OR(F22="Y",J22="Y",M22="Y",P22="Y")," | ","")&"Inactive Customer","") -> Settlement Authorization
A23: SYN-CLM-0022 | B23: Synthetic Claimant 0022 | C23: Claims Analyst C | D23: Synthetic Policyholder 073, LLC | E23: 43350 | F23: N | J23: Y | K23: 44321 | L23: N | M23: N | P23: N | S23: N | U23: =IF(ISNUMBER(SEARCH("SURGERY",Q23&" "&R23)),"Y","N") -> N | V23: =IF(ISNUMBER(SEARCH("MMI",Q23&" "&R23)),"Y","N") -> N | W23: =IF(ISNUMBER(SEARCH("DENIED TREATMENT",Q23&" "&R23)),"Y","N") -> N | X23: =IF(ISNUMBER(SEARCH("SPECIALIST CONSULTATION",Q23&" "&R23)),"Y","N") -> N | Y23: =IF(ISNUMBER(SEARCH("NON-RENEWED ACCOUNT",Q23&" "&R23)),"Y","N") -> N | Z23: =IF(ISNUMBER(SEARCH("MSA ELIGIBLE",Q23&" "&R23)),"Y","N") -> N | AA23: =COUNTIF(F23,"Y")+COUNTIF(J23,"Y")+COUNTIF(M23,"Y")+COUNTIF(P23,"Y")+COUNTIF(S23,"Y") -> 1 | AB23: =IF(AA23=5,"MAXIMUM MULTI-SIGNAL",IF(AA23=4,"HIGH MULTI-SIGNAL",IF(AA23=3,"ELEVATED MULTI-SIGNAL",IF(AA23=2,"MULTI-SIGNAL","SINGLE-SIGNAL")))) -> SINGLE-SIGNAL | AC23: =IF(F23="Y","Settlement Authorization","")&IF(J23="Y",IF(F23="Y"," | ","")&"Open Stipulation","")&IF(M23="Y",IF(OR(F23="Y",J23="Y")," | ","")&"Pending QME","")&IF(P23="Y",IF(OR(F23="Y",J23="Y",M23="Y")," | ","")&"Automated Claim Alert","")&IF(S23="Y",IF(OR(F23="Y",J23="Y",M23="Y",P23="Y")," | ","")&"Inactive Customer","") -> Open Stipulation
A24: SYN-CLM-0023 | B24: Synthetic Claimant 0023 | C24: Claims Analyst C | D24: Synthetic Policyholder 040, LLC | E24: 43869 | F24: N | J24: N | M24: Y | N24: 45391 | O24: Synthetic QME Evaluator 20 | P24: N | S24: N | U24: =IF(ISNUMBER(SEARCH("SURGERY",Q24&" "&R24)),"Y","N") -> N | V24: =IF(ISNUMBER(SEARCH("MMI",Q24&" "&R24)),"Y","N") -> N | W24: =IF(ISNUMBER(SEARCH("DENIED TREATMENT",Q24&" "&R24)),"Y","N") -> N | X24: =IF(ISNUMBER(SEARCH("SPECIALIST CONSULTATION",Q24&" "&R24)),"Y","N") -> N | Y24: =IF(ISNUMBER(SEARCH("NON-RENEWED ACCOUNT",Q24&" "&R24)),"Y","N") -> N | Z24: =IF(ISNUMBER(SEARCH("MSA ELIGIBLE",Q24&" "&R24)),"Y","N") -> N | AA24: =COUNTIF(F24,"Y")+COUNTIF(J24,"Y")+COUNTIF(M24,"Y")+COUNTIF(P24,"Y")+COUNTIF(S24,"Y") -> 1 | AB24: =IF(AA24=5,"MAXIMUM MULTI-SIGNAL",IF(AA24=4,"HIGH MULTI-SIGNAL",IF(AA24=3,"ELEVATED MULTI-SIGNAL",IF(AA24=2,"MULTI-SIGNAL","SINGLE-SIGNAL")))) -> SINGLE-SIGNAL | AC24: =IF(F24="Y","Settlement Authorization","")&IF(J24="Y",IF(F24="Y"," | ","")&"Open Stipulation","")&IF(M24="Y",IF(OR(F24="Y",J24="Y")," | ","")&"Pending QME","")&IF(P24="Y",IF(OR(F24="Y",J24="Y",M24="Y")," | ","")&"Automated Claim Alert","")&IF(S24="Y",IF(OR(F24="Y",J24="Y",M24="Y",P24="Y")," | ","")&"Inactive Customer","") -> Pending QME
A25: SYN-CLM-0024 | B25: Synthetic Claimant 0024 | C25: Claims Analyst C | D25: Synthetic Policyholder 155, LLC | E25: 43616 | F25: N | J25: N | M25: N | P25: Y | Q25: Non-Renewed Account; MSA Eligible in Next 3 Years; Denied Treatment Requests | S25: N | U25: =IF(ISNUMBER(SEARCH("SURGERY",Q25&" "&R25)),"Y","N") -> N | V25: =IF(ISNUMBER(SEARCH("MMI",Q25&" "&R25)),"Y","N") -> N | W25: =IF(ISNUMBER(SEARCH("DENIED TREATMENT",Q25&" "&R25)),"Y","N") -> Y | X25: =IF(ISNUMBER(SEARCH("SPECIALIST CONSULTATION",Q25&" "&R25)),"Y","N") -> N | Y25: =IF(ISNUMBER(SEARCH("NON-RENEWED ACCOUNT",Q25&" "&R25)),"Y","N") -> Y | Z25: =IF(ISNUMBER(SEARCH("MSA ELIGIBLE",Q25&" "&R25)),"Y","N") -> Y | AA25: =COUNTIF(F25,"Y")+COUNTIF(J25,"Y")+COUNTIF(M25,"Y")+COUNTIF(P25,"Y")+COUNTIF(S25,"Y") -> 1 | AB25: =IF(AA25=5,"MAXIMUM MULTI-SIGNAL",IF(AA25=4,"HIGH MULTI-SIGNAL",IF(AA25=3,"ELEVATED MULTI-SIGNAL",IF(AA25=2,"MULTI-SIGNAL","SINGLE-SIGNAL")))) -> SINGLE-SIGNAL | AC25: =IF(F25="Y","Settlement Authorization","")&IF(J25="Y",IF(F25="Y"," | ","")&"Open Stipulation","")&IF(M25="Y",IF(OR(F25="Y",J25="Y")," | ","")&"Pending QME","")&IF(P25="Y",IF(OR(F25="Y",J25="Y",M25="Y")," | ","")&"Automated Claim Alert","")&IF(S25="Y",IF(OR(F25="Y",J25="Y",M25="Y",P25="Y")," | ","")&"Inactive Customer","") -> Automated Claim Alert
A26: SYN-CLM-0025 | B26: Synthetic Claimant 0025 | C26: Claims Analyst C | D26: Synthetic Policyholder 090, LLC | E26: 45098 | F26: Y | G26: 141000 | H26: Synthetic Approver 12 | I26: 45846 | J26: N | L26: N | M26: N | P26: N | S26: N | U26: =IF(ISNUMBER(SEARCH("SURGERY",Q26&" "&R26)),"Y","N") -> N | V26: =IF(ISNUMBER(SEARCH("MMI",Q26&" "&R26)),"Y","N") -> N | W26: =IF(ISNUMBER(SEARCH("DENIED TREATMENT",Q26&" "&R26)),"Y","N") -> N | X26: =IF(ISNUMBER(SEARCH("SPECIALIST CONSULTATION",Q26&" "&R26)),"Y","N") -> N | Y26: =IF(ISNUMBER(SEARCH("NON-RENEWED ACCOUNT",Q26&" "&R26)),"Y","N") -> N | Z26: =IF(ISNUMBER(SEARCH("MSA ELIGIBLE",Q26&" "&R26)),"Y","N") -> N | AA26: =COUNTIF(F26,"Y")+COUNTIF(J26,"Y")+COUNTIF(M26,"Y")+COUNTIF(P26,"Y")+COUNTIF(S26,"Y") -> 1 | AB26: =IF(AA26=5,"MAXIMUM MULTI-SIGNAL",IF(AA26=4,"HIGH MULTI-SIGNAL",IF(AA26=3,"ELEVATED MULTI-SIGNAL",IF(AA26=2,"MULTI-SIGNAL","SINGLE-SIGNAL")))) -> SINGLE-SIGNAL | AC26: =IF(F26="Y","Settlement Authorization","")&IF(J26="Y",IF(F26="Y"," | ","")&"Open Stipulation","")&IF(M26="Y",IF(OR(F26="Y",J26="Y")," | ","")&"Pending QME","")&IF(P26="Y",IF(OR(F26="Y",J26="Y",M26="Y")," | ","")&"Automated Claim Alert","")&IF(S26="Y",IF(OR(F26="Y",J26="Y",M26="Y",P26="Y")," | ","")&"Inactive Customer","") -> Settlement Authorization
A27: SYN-CLM-0026 | B27: Synthetic Claimant 0026 | C27: Claims Analyst C | D27: Synthetic Policyholder 042, LLC | E27: 43998 | F27: Y | G27: 31750 | H27: Synthetic Approver 12 | I27: 44620 | J27: N | L27: N | M27: N | P27: Y | Q27: MSA Eligible in Next 3 Years | S27: N | U27: =IF(ISNUMBER(SEARCH("SURGERY",Q27&" "&R27)),"Y","N") -> N | V27: =IF(ISNUMBER(SEARCH("MMI",Q27&" "&R27)),"Y","N") -> N | W27: =IF(ISNUMBER(SEARCH("DENIED TREATMENT",Q27&" "&R27)),"Y","N") -> N | X27: =IF(ISNUMBER(SEARCH("SPECIALIST CONSULTATION",Q27&" "&R27)),"Y","N") -> N | Y27: =IF(ISNUMBER(SEARCH("NON-RENEWED ACCOUNT",Q27&" "&R27)),"Y","N") -> N | Z27: =IF(ISNUMBER(SEARCH("MSA ELIGIBLE",Q27&" "&R27)),"Y","N") -> Y | AA27: =COUNTIF(F27,"Y")+COUNTIF(J27,"Y")+COUNTIF(M27,"Y")+COUNTIF(P27,"Y")+COUNTIF(S27,"Y") -> 2 | AB27: =IF(AA27=5,"MAXIMUM MULTI-SIGNAL",IF(AA27=4,"HIGH MULTI-SIGNAL",IF(AA27=3,"ELEVATED MULTI-SIGNAL",IF(AA27=2,"MULTI-SIGNAL","SINGLE-SIGNAL")))) -> MULTI-SIGNAL | AC27: =IF(F27="Y","Settlement Authorization","")&IF(J27="Y",IF(F27="Y"," | ","")&"Open Stipulation","")&IF(M27="Y",IF(OR(F27="Y",J27="Y")," | ","")&"Pending QME","")&IF(P27="Y",IF(OR(F27="Y",J27="Y",M27="Y")," | ","")&"Automated Claim Alert","")&IF(S27="Y",IF(OR(F27="Y",J27="Y",M27="Y",P27="Y")," | ","")&"Inactive Customer","") -> Settlement Authorization | Automated Claim Alert
A28: SYN-CLM-0027 | B28: Synthetic Claimant 0027 | C28: Claims Analyst C | D28: Synthetic Policyholder 104, LLC | E28: 44367 | F28: N | J28: N | M28: N | P28: N | S28: Y | T28: 46317 | U28: =IF(ISNUMBER(SEARCH("SURGERY",Q28&" "&R28)),"Y","N") -> N | V28: =IF(ISNUMBER(SEARCH("MMI",Q28&" "&R28)),"Y","N") -> N | W28: =IF(ISNUMBER(SEARCH("DENIED TREATMENT",Q28&" "&R28)),"Y","N") -> N | X28: =IF(ISNUMBER(SEARCH("SPECIALIST CONSULTATION",Q28&" "&R28)),"Y","N") -> N | Y28: =IF(ISNUMBER(SEARCH("NON-RENEWED ACCOUNT",Q28&" "&R28)),"Y","N") -> N | Z28: =IF(ISNUMBER(SEARCH("MSA ELIGIBLE",Q28&" "&R28)),"Y","N") -> N | AA28: =COUNTIF(F28,"Y")+COUNTIF(J28,"Y")+COUNTIF(M28,"Y")+COUNTIF(P28,"Y")+COUNTIF(S28,"Y") -> 1 | AB28: =IF(AA28=5,"MAXIMUM MULTI-SIGNAL",IF(AA28=4,"HIGH MULTI-SIGNAL",IF(AA28=3,"ELEVATED MULTI-SIGNAL",IF(AA28=2,"MULTI-SIGNAL","SINGLE-SIGNAL")))) -> SINGLE-SIGNAL | AC28: =IF(F28="Y","Settlement Authorization","")&IF(J28="Y",IF(F28="Y"," | ","")&"Open Stipulation","")&IF(M28="Y",IF(OR(F28="Y",J28="Y")," | ","")&"Pending QME","")&IF(P28="Y",IF(OR(F28="Y",J28="Y",M28="Y")," | ","")&"Automated Claim Alert","")&IF(S28="Y",IF(OR(F28="Y",J28="Y",M28="Y",P28="Y")," | ","")&"Inactive Customer","") -> Inactive Customer
A29: SYN-CLM-0028 | B29: Synthetic Claimant 0028 | C29: Claims Analyst C | D29: Synthetic Policyholder 096, LLC | E29: 44646 | F29: N | J29: Y | K29: 45828 | L29: N | M29: N | P29: N | S29: N | U29: =IF(ISNUMBER(SEARCH("SURGERY",Q29&" "&R29)),"Y","N") -> N | V29: =IF(ISNUMBER(SEARCH("MMI",Q29&" "&R29)),"Y","N") -> N | W29: =IF(ISNUMBER(SEARCH("DENIED TREATMENT",Q29&" "&R29)),"Y","N") -> N | X29: =IF(ISNUMBER(SEARCH("SPECIALIST CONSULTATION",Q29&" "&R29)),"Y","N") -> N | Y29: =IF(ISNUMBER(SEARCH("NON-RENEWED ACCOUNT",Q29&" "&R29)),"Y","N") -> N | Z29: =IF(ISNUMBER(SEARCH("MSA ELIGIBLE",Q29&" "&R29)),"Y","N") -> N | AA29: =COUNTIF(F29,"Y")+COUNTIF(J29,"Y")+COUNTIF(M29,"Y")+COUNTIF(P29,"Y")+COUNTIF(S29,"Y") -> 1 | AB29: =IF(AA29=5,"MAXIMUM MULTI-SIGNAL",IF(AA29=4,"HIGH MULTI-SIGNAL",IF(AA29=3,"ELEVATED MULTI-SIGNAL",IF(AA29=2,"MULTI-SIGNAL","SINGLE-SIGNAL")))) -> SINGLE-SIGNAL | AC29: =IF(F29="Y","Settlement Authorization","")&IF(J29="Y",IF(F29="Y"," | ","")&"Open Stipulation","")&IF(M29="Y",IF(OR(F29="Y",J29="Y")," | ","")&"Pending QME","")&IF(P29="Y",IF(OR(F29="Y",J29="Y",M29="Y")," | ","")&"Automated Claim Alert","")&IF(S29="Y",IF(OR(F29="Y",J29="Y",M29="Y",P29="Y")," | ","")&"Inactive Customer","") -> Open Stipulation
A30: SYN-CLM-0029 | B30: Synthetic Claimant 0029 | C30: Claims Analyst C | D30: Synthetic Policyholder 089, LLC | E30: 43270 | F30: Y | G30: 115750 | H30: Synthetic Approver 12 | I30: 43606 | J30: N | L30: Y | M30: N | P30: Y | Q30: MSA Eligible in Next 3 Years | S30: Y | T30: 45018 | U30: =IF(ISNUMBER(SEARCH("SURGERY",Q30&" "&R30)),"Y","N") -> N | V30: =IF(ISNUMBER(SEARCH("MMI",Q30&" "&R30)),"Y","N") -> N | W30: =IF(ISNUMBER(SEARCH("DENIED TREATMENT",Q30&" "&R30)),"Y","N") -> N | X30: =IF(ISNUMBER(SEARCH("SPECIALIST CONSULTATION",Q30&" "&R30)),"Y","N") -> N | Y30: =IF(ISNUMBER(SEARCH("NON-RENEWED ACCOUNT",Q30&" "&R30)),"Y","N") -> N | Z30: =IF(ISNUMBER(SEARCH("MSA ELIGIBLE",Q30&" "&R30)),"Y","N") -> Y | AA30: =COUNTIF(F30,"Y")+COUNTIF(J30,"Y")+COUNTIF(M30,"Y")+COUNTIF(P30,"Y")+COUNTIF(S30,"Y") -> 3 | AB30: =IF(AA30=5,"MAXIMUM MULTI-SIGNAL",IF(AA30=4,"HIGH MULTI-SIGNAL",IF(AA30=3,"ELEVATED MULTI-SIGNAL",IF(AA30=2,"MULTI-SIGNAL","SINGLE-SIGNAL")))) -> ELEVATED MULTI-SIGNAL | AC30: =IF(F30="Y","Settlement Authorization","")&IF(J30="Y",IF(F30="Y"," | ","")&"Open Stipulation","")&IF(M30="Y",IF(OR(F30="Y",J30="Y")," | ","")&"Pending QME","")&IF(P30="Y",IF(OR(F30="Y",J30="Y",M30="Y")," | ","")&"Automated Claim Alert","")&IF(S30="Y",IF(OR(F30="Y",J30="Y",M30="Y",P30="Y")," | ","")&"Inactive Customer","") -> Settlement Authorization | Automated Claim Alert | Inactive Customer
A31: SYN-CLM-0030 | B31: Synthetic Claimant 0030 | C31: Claims Analyst C | D31: Synthetic Policyholder 085, LLC | E31: 43230 | F31: Y | G31: 155750 | H31: Synthetic Approver 02 | I31: 43559 | J31: N | L31: N | M31: N | P31: N | S31: Y | T31: 44589 | U31: =IF(ISNUMBER(SEARCH("SURGERY",Q31&" "&R31)),"Y","N") -> N | V31: =IF(ISNUMBER(SEARCH("MMI",Q31&" "&R31)),"Y","N") -> N | W31: =IF(ISNUMBER(SEARCH("DENIED TREATMENT",Q31&" "&R31)),"Y","N") -> N | X31: =IF(ISNUMBER(SEARCH("SPECIALIST CONSULTATION",Q31&" "&R31)),"Y","N") -> N | Y31: =IF(ISNUMBER(SEARCH("NON-RENEWED ACCOUNT",Q31&" "&R31)),"Y","N") -> N | Z31: =IF(ISNUMBER(SEARCH("MSA ELIGIBLE",Q31&" "&R31)),"Y","N") -> N | AA31: =COUNTIF(F31,"Y")+COUNTIF(J31,"Y")+COUNTIF(M31,"Y")+COUNTIF(P31,"Y")+COUNTIF(S31,"Y") -> 2 | AB31: =IF(AA31=5,"MAXIMUM MULTI-SIGNAL",IF(AA31=4,"HIGH MULTI-SIGNAL",IF(AA31=3,"ELEVATED MULTI-SIGNAL",IF(AA31=2,"MULTI-SIGNAL","SINGLE-SIGNAL")))) -> MULTI-SIGNAL | AC31: =IF(F31="Y","Settlement Authorization","")&IF(J31="Y",IF(F31="Y"," | ","")&"Open Stipulation","")&IF(M31="Y",IF(OR(F31="Y",J31="Y")," | ","")&"Pending QME","")&IF(P31="Y",IF(OR(F31="Y",J31="Y",M31="Y")," | ","")&"Automated Claim Alert","")&IF(S31="Y",IF(OR(F31="Y",J31="Y",M31="Y",P31="Y")," | ","")&"Inactive Customer","") -> Settlement Authorization | Inactive Customer
A32: SYN-CLM-0031 | B32: Synthetic Claimant 0031 | C32: Claims Analyst C | D32: Synthetic Policyholder 048, LLC | E32: 43595 | F32: Y | G32: 170500 | H32: Synthetic Approver 06 | I32: 44131 | J32: N | L32: N | M32: N | P32: N | S32: Y | T32: 45135 | U32: =IF(ISNUMBER(SEARCH("SURGERY",Q32&" "&R32)),"Y","N") -> N | V32: =IF(ISNUMBER(SEARCH("MMI",Q32&" "&R32)),"Y","N") -> N | W32: =IF(ISNUMBER(SEARCH("DENIED TREATMENT",Q32&" "&R32)),"Y","N") -> N | X32: =IF(ISNUMBER(SEARCH("SPECIALIST CONSULTATION",Q32&" "&R32)),"Y","N") -> N | Y32: =IF(ISNUMBER(SEARCH("NON-RENEWED ACCOUNT",Q32&" "&R32)),"Y","N") -> N | Z32: =IF(ISNUMBER(SEARCH("MSA ELIGIBLE",Q32&" "&R32)),"Y","N") -> N | AA32: =COUNTIF(F32,"Y")+COUNTIF(J32,"Y")+COUNTIF(M32,"Y")+COUNTIF(P32,"Y")+COUNTIF(S32,"Y") -> 2 | AB32: =IF(AA32=5,"MAXIMUM MULTI-SIGNAL",IF(AA32=4,"HIGH MULTI-SIGNAL",IF(AA32=3,"ELEVATED MULTI-SIGNAL",IF(AA32=2,"MULTI-SIGNAL","SINGLE-SIGNAL")))) -> MULTI-SIGNAL | AC32: =IF(F32="Y","Settlement Authorization","")&IF(J32="Y",IF(F32="Y"," | ","")&"Open Stipulation","")&IF(M32="Y",IF(OR(F32="Y",J32="Y")," | ","")&"Pending QME","")&IF(P32="Y",IF(OR(F32="Y",J32="Y",M32="Y")," | ","")&"Automated Claim Alert","")&IF(S32="Y",IF(OR(F32="Y",J32="Y",M32="Y",P32="Y")," | ","")&"Inactive Customer","") -> Settlement Authorization | Inactive Customer
A33: SYN-CLM-0032 | B33: Synthetic Claimant 0032 | C33: Claims Analyst D | D33: Synthetic Policyholder 004, LLC | E33: 45156 | F33: Y | G33: 122250 | H33: Synthetic Approver 02 | I33: 45229 | J33: N | L33: N | M33: N | P33: N | S33: N | U33: =IF(ISNUMBER(SEARCH("SURGERY",Q33&" "&R33)),"Y","N") -> N | V33: =IF(ISNUMBER(SEARCH("MMI",Q33&" "&R33)),"Y","N") -> N | W33: =IF(ISNUMBER(SEARCH("DENIED TREATMENT",Q33&" "&R33)),"Y","N") -> N | X33: =IF(ISNUMBER(SEARCH("SPECIALIST CONSULTATION",Q33&" "&R33)),"Y","N") -> N | Y33: =IF(ISNUMBER(SEARCH("NON-RENEWED ACCOUNT",Q33&" "&R33)),"Y","N") -> N | Z33: =IF(ISNUMBER(SEARCH("MSA ELIGIBLE",Q33&" "&R33)),"Y","N") -> N | AA33: =COUNTIF(F33,"Y")+COUNTIF(J33,"Y")+COUNTIF(M33,"Y")+COUNTIF(P33,"Y")+COUNTIF(S33,"Y") -> 1 | AB33: =IF(AA33=5,"MAXIMUM MULTI-SIGNAL",IF(AA33=4,"HIGH MULTI-SIGNAL",IF(AA33=3,"ELEVATED MULTI-SIGNAL",IF(AA33=2,"MULTI-SIGNAL","SINGLE-SIGNAL")))) -> SINGLE-SIGNAL | AC33: =IF(F33="Y","Settlement Authorization","")&IF(J33="Y",IF(F33="Y"," | ","")&"Open Stipulation","")&IF(M33="Y",IF(OR(F33="Y",J33="Y")," | ","")&"Pending QME","")&IF(P33="Y",IF(OR(F33="Y",J33="Y",M33="Y")," | ","")&"Automated Claim Alert","")&IF(S33="Y",IF(OR(F33="Y",J33="Y",M33="Y",P33="Y")," | ","")&"Inactive Customer","") -> Settlement Authorization
A34: SYN-CLM-0033 | B34: Synthetic Claimant 0033 | C34: Claims Analyst E | D34: Synthetic Policyholder 125, LLC | E34: 45236 | F34: N | J34: N | M34: N | P34: N | S34: Y | T34: 46923 | U34: =IF(ISNUMBER(SEARCH("SURGERY",Q34&" "&R34)),"Y","N") -> N | V34: =IF(ISNUMBER(SEARCH("MMI",Q34&" "&R34)),"Y","N") -> N | W34: =IF(ISNUMBER(SEARCH("DENIED TREATMENT",Q34&" "&R34)),"Y","N") -> N | X34: =IF(ISNUMBER(SEARCH("SPECIALIST CONSULTATION",Q34&" "&R34)),"Y","N") -> N | Y34: =IF(ISNUMBER(SEARCH("NON-RENEWED ACCOUNT",Q34&" "&R34)),"Y","N") -> N | Z34: =IF(ISNUMBER(SEARCH("MSA ELIGIBLE",Q34&" "&R34)),"Y","N") -> N | AA34: =COUNTIF(F34,"Y")+COUNTIF(J34,"Y")+COUNTIF(M34,"Y")+COUNTIF(P34,"Y")+COUNTIF(S34,"Y") -> 1 | AB34: =IF(AA34=5,"MAXIMUM MULTI-SIGNAL",IF(AA34=4,"HIGH MULTI-SIGNAL",IF(AA34=3,"ELEVATED MULTI-SIGNAL",IF(AA34=2,"MULTI-SIGNAL","SINGLE-SIGNAL")))) -> SINGLE-SIGNAL | AC34: =IF(F34="Y","Settlement Authorization","")&IF(J34="Y",IF(F34="Y"," | ","")&"Open Stipulation","")&IF(M34="Y",IF(OR(F34="Y",J34="Y")," | ","")&"Pending QME","")&IF(P34="Y",IF(OR(F34="Y",J34="Y",M34="Y")," | ","")&"Automated Claim Alert","")&IF(S34="Y",IF(OR(F34="Y",J34="Y",M34="Y",P34="Y")," | ","")&"Inactive Customer","") -> Inactive Customer
A35: SYN-CLM-0034 | B35: Synthetic Claimant 0034 | C35: Claims Analyst E | D35: Synthetic Policyholder 019, LLC | E35: 43929 | F35: Y | G35: 71250 | H35: Synthetic Approver 01 | I35: 44890 | J35: N | L35: Y | M35: N | P35: N | S35: N | U35: =IF(ISNUMBER(SEARCH("SURGERY",Q35&" "&R35)),"Y","N") -> N | V35: =IF(ISNUMBER(SEARCH("MMI",Q35&" "&R35)),"Y","N") -> N | W35: =IF(ISNUMBER(SEARCH("DENIED TREATMENT",Q35&" "&R35)),"Y","N") -> N | X35: =IF(ISNUMBER(SEARCH("SPECIALIST CONSULTATION",Q35&" "&R35)),"Y","N") -> N | Y35: =IF(ISNUMBER(SEARCH("NON-RENEWED ACCOUNT",Q35&" "&R35)),"Y","N") -> N | Z35: =IF(ISNUMBER(SEARCH("MSA ELIGIBLE",Q35&" "&R35)),"Y","N") -> N | AA35: =COUNTIF(F35,"Y")+COUNTIF(J35,"Y")+COUNTIF(M35,"Y")+COUNTIF(P35,"Y")+COUNTIF(S35,"Y") -> 1 | AB35: =IF(AA35=5,"MAXIMUM MULTI-SIGNAL",IF(AA35=4,"HIGH MULTI-SIGNAL",IF(AA35=3,"ELEVATED MULTI-SIGNAL",IF(AA35=2,"MULTI-SIGNAL","SINGLE-SIGNAL")))) -> SINGLE-SIGNAL | AC35: =IF(F35="Y","Settlement Authorization","")&IF(J35="Y",IF(F35="Y"," | ","")&"Open Stipulation","")&IF(M35="Y",IF(OR(F35="Y",J35="Y")," | ","")&"Pending QME","")&IF(P35="Y",IF(OR(F35="Y",J35="Y",M35="Y")," | ","")&"Automated Claim Alert","")&IF(S35="Y",IF(OR(F35="Y",J35="Y",M35="Y",P35="Y")," | ","")&"Inactive Customer","") -> Settlement Authorization
A36: SYN-CLM-0035 | B36: Synthetic Claimant 0035 | C36: Claims Analyst E | D36: Synthetic Policyholder 014, LLC | E36: 45664 | F36: N | J36: Y | K36: 46697 | L36: Y | M36: N | P36: N | S36: N | U36: =IF(ISNUMBER(SEARCH("SURGERY",Q36&" "&R36)),"Y","N") -> N | V36: =IF(ISNUMBER(SEARCH("MMI",Q36&" "&R36)),"Y","N") -> N | W36: =IF(ISNUMBER(SEARCH("DENIED TREATMENT",Q36&" "&R36)),"Y","N") -> N | X36: =IF(ISNUMBER(SEARCH("SPECIALIST CONSULTATION",Q36&" "&R36)),"Y","N") -> N | Y36: =IF(ISNUMBER(SEARCH("NON-RENEWED ACCOUNT",Q36&" "&R36)),"Y","N") -> N | Z36: =IF(ISNUMBER(SEARCH("MSA ELIGIBLE",Q36&" "&R36)),"Y","N") -> N | AA36: =COUNTIF(F36,"Y")+COUNTIF(J36,"Y")+COUNTIF(M36,"Y")+COUNTIF(P36,"Y")+COUNTIF(S36,"Y") -> 1 | AB36: =IF(AA36=5,"MAXIMUM MULTI-SIGNAL",IF(AA36=4,"HIGH MULTI-SIGNAL",IF(AA36=3,"ELEVATED MULTI-SIGNAL",IF(AA36=2,"MULTI-SIGNAL","SINGLE-SIGNAL")))) -> SINGLE-SIGNAL | AC36: =IF(F36="Y","Settlement Authorization","")&IF(J36="Y",IF(F36="Y"," | ","")&"Open Stipulation","")&IF(M36="Y",IF(OR(F36="Y",J36="Y")," | ","")&"Pending QME","")&IF(P36="Y",IF(OR(F36="Y",J36="Y",M36="Y")," | ","")&"Automated Claim Alert","")&IF(S36="Y",IF(OR(F36="Y",J36="Y",M36="Y",P36="Y")," | ","")&"Inactive Customer","") -> Open Stipulation
A37: SYN-CLM-0036 | B37: Synthetic Claimant 0036 | C37: Claims Analyst E | D37: Synthetic Policyholder 170, LLC | E37: 43425 | F37: Y | G37: 69000 | H37: Synthetic Approver 09 | I37: 44401 | J37: Y | K37: 43983 | L37: N | M37: N | P37: N | S37: N | U37: =IF(ISNUMBER(SEARCH("SURGERY",Q37&" "&R37)),"Y","N") -> N | V37: =IF(ISNUMBER(SEARCH("MMI",Q37&" "&R37)),"Y","N") -> N | W37: =IF(ISNUMBER(SEARCH("DENIED TREATMENT",Q37&" "&R37)),"Y","N") -> N | X37: =IF(ISNUMBER(SEARCH("SPECIALIST CONSULTATION",Q37&" "&R37)),"Y","N") -> N | Y37: =IF(ISNUMBER(SEARCH("NON-RENEWED ACCOUNT",Q37&" "&R37)),"Y","N") -> N | Z37: =IF(ISNUMBER(SEARCH("MSA ELIGIBLE",Q37&" "&R37)),"Y","N") -> N | AA37: =COUNTIF(F37,"Y")+COUNTIF(J37,"Y")+COUNTIF(M37,"Y")+COUNTIF(P37,"Y")+COUNTIF(S37,"Y") -> 2 | AB37: =IF(AA37=5,"MAXIMUM MULTI-SIGNAL",IF(AA37=4,"HIGH MULTI-SIGNAL",IF(AA37=3,"ELEVATED MULTI-SIGNAL",IF(AA37=2,"MULTI-SIGNAL","SINGLE-SIGNAL")))) -> MULTI-SIGNAL | AC37: =IF(F37="Y","Settlement Authorization","")&IF(J37="Y",IF(F37="Y"," | ","")&"Open Stipulation","")&IF(M37="Y",IF(OR(F37="Y",J37="Y")," | ","")&"Pending QME","")&IF(P37="Y",IF(OR(F37="Y",J37="Y",M37="Y")," | ","")&"Automated Claim Alert","")&IF(S37="Y",IF(OR(F37="Y",J37="Y",M37="Y",P37="Y")," | ","")&"Inactive Customer","") -> Settlement Authorization | Open Stipulation
A38: SYN-CLM-0037 | B38: Synthetic Claimant 0037 | C38: Claims Analyst E | D38: Synthetic Policyholder 162, LLC | E38: 43707 | F38: Y | G38: 111000 | H38: Synthetic Approver 04 | I38: 44762 | J38: N | L38: Y | M38: N | P38: Y | Q38: MSA Eligible in Next 3 Years; Surgery Requested; MMI Date Reported | R38: Denied Treatment Requests | S38: N | U38: =IF(ISNUMBER(SEARCH("SURGERY",Q38&" "&R38)),"Y","N") -> Y | V38: =IF(ISNUMBER(SEARCH("MMI",Q38&" "&R38)),"Y","N") -> Y | W38: =IF(ISNUMBER(SEARCH("DENIED TREATMENT",Q38&" "&R38)),"Y","N") -> Y | X38: =IF(ISNUMBER(SEARCH("SPECIALIST CONSULTATION",Q38&" "&R38)),"Y","N") -> N | Y38: =IF(ISNUMBER(SEARCH("NON-RENEWED ACCOUNT",Q38&" "&R38)),"Y","N") -> N | Z38: =IF(ISNUMBER(SEARCH("MSA ELIGIBLE",Q38&" "&R38)),"Y","N") -> Y | AA38: =COUNTIF(F38,"Y")+COUNTIF(J38,"Y")+COUNTIF(M38,"Y")+COUNTIF(P38,"Y")+COUNTIF(S38,"Y") -> 2 | AB38: =IF(AA38=5,"MAXIMUM MULTI-SIGNAL",IF(AA38=4,"HIGH MULTI-SIGNAL",IF(AA38=3,"ELEVATED MULTI-SIGNAL",IF(AA38=2,"MULTI-SIGNAL","SINGLE-SIGNAL")))) -> MULTI-SIGNAL | AC38: =IF(F38="Y","Settlement Authorization","")&IF(J38="Y",IF(F38="Y"," | ","")&"Open Stipulation","")&IF(M38="Y",IF(OR(F38="Y",J38="Y")," | ","")&"Pending QME","")&IF(P38="Y",IF(OR(F38="Y",J38="Y",M38="Y")," | ","")&"Automated Claim Alert","")&IF(S38="Y",IF(OR(F38="Y",J38="Y",M38="Y",P38="Y")," | ","")&"Inactive Customer","") -> Settlement Authorization | Automated Claim Alert
A39: SYN-CLM-0038 | B39: Synthetic Claimant 0038 | C39: Claims Analyst E | D39: Synthetic Policyholder 113, LLC | E39: 44470 | F39: Y | G39: 42750 | H39: Synthetic Approver 01 | I39: 45899 | J39: N | L39: N | M39: N | P39: N | S39: N | U39: =IF(ISNUMBER(SEARCH("SURGERY",Q39&" "&R39)),"Y","N") -> N | V39: =IF(ISNUMBER(SEARCH("MMI",Q39&" "&R39)),"Y","N") -> N | W39: =IF(ISNUMBER(SEARCH("DENIED TREATMENT",Q39&" "&R39)),"Y","N") -> N | X39: =IF(ISNUMBER(SEARCH("SPECIALIST CONSULTATION",Q39&" "&R39)),"Y","N") -> N | Y39: =IF(ISNUMBER(SEARCH("NON-RENEWED ACCOUNT",Q39&" "&R39)),"Y","N") -> N | Z39: =IF(ISNUMBER(SEARCH("MSA ELIGIBLE",Q39&" "&R39)),"Y","N") -> N | AA39: =COUNTIF(F39,"Y")+COUNTIF(J39,"Y")+COUNTIF(M39,"Y")+COUNTIF(P39,"Y")+COUNTIF(S39,"Y") -> 1 | AB39: =IF(AA39=5,"MAXIMUM MULTI-SIGNAL",IF(AA39=4,"HIGH MULTI-SIGNAL",IF(AA39=3,"ELEVATED MULTI-SIGNAL",IF(AA39=2,"MULTI-SIGNAL","SINGLE-SIGNAL")))) -> SINGLE-SIGNAL | AC39: =IF(F39="Y","Settlement Authorization","")&IF(J39="Y",IF(F39="Y"," | ","")&"Open Stipulation","")&IF(M39="Y",IF(OR(F39="Y",J39="Y")," | ","")&"Pending QME","")&IF(P39="Y",IF(OR(F39="Y",J39="Y",M39="Y")," | ","")&"Automated Claim Alert","")&IF(S39="Y",IF(OR(F39="Y",J39="Y",M39="Y",P39="Y")," | ","")&"Inactive Customer","") -> Settlement Authorization
A40: SYN-CLM-0039 | B40: Synthetic Claimant 0039 | C40: Claims Analyst E | D40: Synthetic Policyholder 010, LLC | E40: 44918 | F40: Y | G40: 67250 | H40: Synthetic Approver 07 | I40: 45655 | J40: Y | K40: 45131 | L40: N | M40: N | P40: N | S40: N | U40: =IF(ISNUMBER(SEARCH("SURGERY",Q40&" "&R40)),"Y","N") -> N | V40: =IF(ISNUMBER(SEARCH("MMI",Q40&" "&R40)),"Y","N") -> N | W40: =IF(ISNUMBER(SEARCH("DENIED TREATMENT",Q40&" "&R40)),"Y","N") -> N | X40: =IF(ISNUMBER(SEARCH("SPECIALIST CONSULTATION",Q40&" "&R40)),"Y","N") -> N | Y40: =IF(ISNUMBER(SEARCH("NON-RENEWED ACCOUNT",Q40&" "&R40)),"Y","N") -> N | Z40: =IF(ISNUMBER(SEARCH("MSA ELIGIBLE",Q40&" "&R40)),"Y","N") -> N | AA40: =COUNTIF(F40,"Y")+COUNTIF(J40,"Y")+COUNTIF(M40,"Y")+COUNTIF(P40,"Y")+COUNTIF(S40,"Y") -> 2 | AB40: =IF(AA40=5,"MAXIMUM MULTI-SIGNAL",IF(AA40=4,"HIGH MULTI-SIGNAL",IF(AA40=3,"ELEVATED MULTI-SIGNAL",IF(AA40=2,"MULTI-SIGNAL","SINGLE-SIGNAL")))) -> MULTI-SIGNAL | AC40: =IF(F40="Y","Settlement Authorization","")&IF(J40="Y",IF(F40="Y"," | ","")&"Open Stipulation","")&IF(M40="Y",IF(OR(F40="Y",J40="Y")," | ","")&"Pending QME","")&IF(P40="Y",IF(OR(F40="Y",J40="Y",M40="Y")," | ","")&"Automated Claim Alert","")&IF(S40="Y",IF(OR(F40="Y",J40="Y",M40="Y",P40="Y")," | ","")&"Inactive Customer","") -> Settlement Authorization | Open Stipulation
...

Sheet DASHBOARD
A1: SYNTHETIC CLAIMS OPPORTUNITY DASHBOARD
A3: Fictional reporting date: December 31, 2031 | Metrics are formula-linked to MASTER DATA.
A5: Total Claims | C5: 5 Indicators | E5: 4 Indicators | G5: 3 Indicators | I5: 2 Indicators | K5: 1 Indicator
A6: =COUNTA('MASTER DATA'!A2:A561) -> 560 | C6: =COUNTIF('MASTER DATA'!AA2:AA561,5) -> 0 | E6: =COUNTIF('MASTER DATA'!AA2:AA561,4) -> 6 | G6: =COUNTIF('MASTER DATA'!AA2:AA561,3) -> 45 | I6: =COUNTIF('MASTER DATA'!AA2:AA561,2) -> 152 | K6: =COUNTIF('MASTER DATA'!AA2:AA561,1) -> 357
A9: Claims by Analyst | D9: Claims by Signal Level | G9: Claims by Indicator Type | J9: Claims by Source Report Count
A10: Claims Analyst | B10: Claims | D10: Opportunity Signal Level | E10: Claims | G10: Indicator | H10: Claims | J10: Reports | K10: Claims
A11: Claims Analyst L | B11: =COUNTIF('MASTER DATA'!C2:C561,A11) -> 76 | D11: MAXIMUM MULTI-SIGNAL | E11: =COUNTIF('MASTER DATA'!AB2:AB561,D11) -> 0 | G11: Settlement Authorization | H11: =COUNTIF('MASTER DATA'!F2:F561,"Y") -> 333 | J11: 1 | K11: =COUNTIF('MASTER DATA'!AA2:AA561,J11) -> 357
A12: Claims Analyst J | B12: =COUNTIF('MASTER DATA'!C2:C561,A12) -> 63 | D12: HIGH MULTI-SIGNAL | E12: =COUNTIF('MASTER DATA'!AB2:AB561,D12) -> 6 | G12: Open Stipulation Without C&R | H12: =COUNTIF('MASTER DATA'!J2:J561,"Y") -> 106 | J12: 2 | K12: =COUNTIF('MASTER DATA'!AA2:AA561,J12) -> 152
A13: Claims Analyst K | B13: =COUNTIF('MASTER DATA'!C2:C561,A13) -> 60 | D13: ELEVATED MULTI-SIGNAL | E13: =COUNTIF('MASTER DATA'!AB2:AB561,D13) -> 45 | G13: Pending QME | H13: =COUNTIF('MASTER DATA'!M2:M561,"Y") -> 80 | J13: 3 | K13: =COUNTIF('MASTER DATA'!AA2:AA561,J13) -> 45
A14: Claims Analyst C | B14: =COUNTIF('MASTER DATA'!C2:C561,A14) -> 55 | D14: MULTI-SIGNAL | E14: =COUNTIF('MASTER DATA'!AB2:AB561,D14) -> 152 | G14: Automated Claim Alert | H14: =COUNTIF('MASTER DATA'!P2:P561,"Y") -> 152 | J14: 4 | K14: =COUNTIF('MASTER DATA'!AA2:AA561,J14) -> 6
A15: Claims Analyst G | B15: =COUNTIF('MASTER DATA'!C2:C561,A15) -> 55 | D15: SINGLE-SIGNAL | E15: =COUNTIF('MASTER DATA'!AB2:AB561,D15) -> 357 | G15: Inactive Customer | H15: =COUNTIF('MASTER DATA'!S2:S561,"Y") -> 149 | J15: 5 | K15: =COUNTIF('MASTER DATA'!AA2:AA561,J15) -> 0
A16: Claims Analyst F | B16: =COUNTIF('MASTER DATA'!C2:C561,A16) -> 48
A17: Claims Analyst I | B17: =COUNTIF('MASTER DATA'!C2:C561,A17) -> 44
A18: Claims Analyst A | B18: =COUNTIF('MASTER DATA'!C2:C561,A18) -> 42
A19: Claims Analyst B | B19: =COUNTIF('MASTER DATA'!C2:C561,A19) -> 41
A20: Claims Analyst E | B20: =COUNTIF('MASTER DATA'!C2:C561,A20) -> 36
A21: Claims Analyst H | B21: =COUNTIF('MASTER DATA'!C2:C561,A21) -> 23
A22: Claims Analyst D | B22: =COUNTIF('MASTER DATA'!C2:C561,A22) -> 17

Sheet AUDIT CONTROLS
A1: SYNTHETIC DATA RECONCILIATION & AUDIT CONTROLS
A4: Source Report | B4: Claims in Master | C4: Expected from Dashboard | D4: Difference | E4: Control Status | F4: Control Explanation
A5: Settlement Authorization | B5: =COUNTIF('MASTER DATA'!F2:F561,"Y") -> 333 | C5: =DASHBOARD!H11 -> 333 | D5: =B5-C5 -> 0 | E5: =IF(D5=0,"PASS","FAIL") -> PASS | F5: Compares master source membership with dashboard summary.
A6: Open Stipulation Without C&R | B6: =COUNTIF('MASTER DATA'!J2:J561,"Y") -> 106 | C6: =DASHBOARD!H12 -> 106 | D6: =B6-C6 -> 0 | E6: =IF(D6=0,"PASS","FAIL") -> PASS | F6: Compares master source membership with dashboard summary.
A7: Pending QME | B7: =COUNTIF('MASTER DATA'!M2:M561,"Y") -> 80 | C7: =DASHBOARD!H13 -> 80 | D7: =B7-C7 -> 0 | E7: =IF(D7=0,"PASS","FAIL") -> PASS | F7: Compares master source membership with dashboard summary.
A8: Automated Claim Alert | B8: =COUNTIF('MASTER DATA'!P2:P561,"Y") -> 152 | C8: =DASHBOARD!H14 -> 152 | D8: =B8-C8 -> 0 | E8: =IF(D8=0,"PASS","FAIL") -> PASS | F8: Compares master source membership with dashboard summary.
A9: Inactive Customer | B9: =COUNTIF('MASTER DATA'!S2:S561,"Y") -> 149 | C9: =DASHBOARD!H15 -> 149 | D9: =B9-C9 -> 0 | E9: =IF(D9=0,"PASS","FAIL") -> PASS | F9: Compares master source membership with dashboard summary.
A12: Reconciliation Check | B12: Calculated Result | C12: Expected Result | D12: Difference | E12: Status | F12: Purpose
A13: Master row count | B13: =COUNTA('MASTER DATA'!A2:A561) -> 560 | C13: =DASHBOARD!A6 -> 560 | D13: =B13-C13 -> 0 | E13: =IF(D13=0,"PASS","FAIL") -> PASS | F13: Headline total agrees with source.
A14: Unique synthetic claim IDs | B14: =SUMPRODUCT(1/COUNTIF('MASTER DATA'!A2:A561,'MASTER DATA'!A2:A561)) -> 560 | C14: =COUNTA('MASTER DATA'!A2:A561) -> 560 | D14: =B14-C14 -> 0 | E14: =IF(D14=0,"PASS","FAIL") -> PASS | F14: One row per claim ID.
A15: Indicator distribution total | B15: =SUM(B19:B23) -> 560 | C15: =COUNTA('MASTER DATA'!A2:A561) -> 560 | D15: =B15-C15 -> 0 | E15: =IF(D15=0,"PASS","FAIL") -> PASS | F15: All records assigned to exactly one group.
A16: Analyst view record total | B16: =SUM(B27:B38) -> 560 | C16: =COUNTA('MASTER DATA'!A2:A561) -> 560 | D16: =B16-C16 -> 0 | E16: =IF(D16=0,"PASS","FAIL") -> PASS | F16: All analyst views cover the master dataset.
A18: Source Report Membership | B18: Claim Count
A19: Claims appearing on 1 report | B19: =COUNTIF('MASTER DATA'!AA2:AA561,1) -> 357
A20: Claims appearing on 2 reports | B20: =COUNTIF('MASTER DATA'!AA2:AA561,2) -> 152
A21: Claims appearing on 3 reports | B21: =COUNTIF('MASTER DATA'!AA2:AA561,3) -> 45
A22: Claims appearing on 4 reports | B22: =COUNTIF('MASTER DATA'!AA2:AA561,4) -> 6
A23: Claims appearing on 5 reports | B23: =COUNTIF('MASTER DATA'!AA2:AA561,5) -> 0
A24: Claims appearing on 2+ reports | B24: =SUM(B20:B23) -> 203
A26: Analyst View | B26: Record Count
A27: Claims Analyst A | B27: =COUNTA('Claims Analyst A'!A2:A1000) -> 42
A28: Claims Analyst B | B28: =COUNTA('Claims Analyst B'!A2:A1000) -> 41
A29: Claims Analyst C | B29: =COUNTA('Claims Analyst C'!A2:A1000) -> 55
A30: Claims Analyst D | B30: =COUNTA('Claims Analyst D'!A2:A1000) -> 17
A31: Claims Analyst E | B31: =COUNTA('Claims Analyst E'!A2:A1000) -> 36
A32: Claims Analyst F | B32: =COUNTA('Claims Analyst F'!A2:A1000) -> 48
A33: Claims Analyst G | B33: =COUNTA('Claims Analyst G'!A2:A1000) -> 55
A34: Claims Analyst H | B34: =COUNTA('Claims Analyst H'!A2:A1000) -> 23
A35: Claims Analyst I | B35: =COUNTA('Claims Analyst I'!A2:A1000) -> 44
A36: Claims Analyst J | B36: =COUNTA('Claims Analyst J'!A2:A1000) -> 63
A37: Claims Analyst K | B37: =COUNTA('Claims Analyst K'!A2:A1000) -> 60
A38: Claims Analyst L | B38: =COUNTA('Claims Analyst L'!A2:A1000) -> 76

Sheet Claims Analyst A
